Workbook

Sheet Gestion Exigences
B2: Gestion Exigences Projet | R2: Chiffrage Réalisation (SF only) | U2: Revue et Vérification Pendant la Conception
B4: BU | H4: SF
B5: Client | H5: La Rose Blanche
B6: Projet | H6: Digitalisation Groupe
B8: Réf Modèle Document | H8: MD203 | M8: Confidentiel | Usage Client Limité
B9: Version Modèle Document | H9: V1.5
B11: ID | C11: Module | D11: Intitulé Exigence | E11: Effort | F11: Cricité | G11: Niveau d'exigence | H11: Nature | I11: Catégorie | J11: Exigence idenfiée pendant la phase | K11: Description de l'exigence | L11: Source | M11: Desciption de la solution ADDIXO | N11: Ecart entre exigence client et la solution proposée - préciser aussi les limites et hypothèses si applicable | O11: Validation Interne | P11: Validation Interne par: | Q11: Statut Client | R11: HJ Dev | S11: HJ Analyse et Test | T11: Total HJ | U11: Description comment la conception de la solution prend en compte l'exigence client | V11: Conception réalisée par: | W11: Revue conception réalisée par | X11: Vérification de la conception réalisée par | Y11: Preuve de vérification | Z11: Notes
B12: E001 | C12: Core | D12: Migration Cloud | E12: 3 | F12: 3 | R12: 3 | S12: =Tableau3[[#This Row],[HJ Dev]]*(25%+25%) -> 1.5 | T12: =Tableau3[[#This Row],[HJ Analyse et Test]]+Tableau3[[#This Row],[HJ Dev]] -> 4.5 | U12: N/A | V12: N/A | W12: N/A | X12: N/A | Y12: N/A
B13: E002 | C13: Core | D13: Architecture Big Data | E13: 3 | F13: 3 | R13: 2 | S13: =Tableau3[[#This Row],[HJ Dev]]*(25%+25%) -> 1 | T13: =Tableau3[[#This Row],[HJ Analyse et Test]]+Tableau3[[#This Row],[HJ Dev]] -> 3
B14: E003 | C14: Production | D14: Planificaition de la production | G14: Partiellemnt couvert | R14: 0 | S14: =Tableau3[[#This Row],[HJ Dev]]*(25%+25%) -> 0 | T14: =Tableau3[[#This Row],[HJ Analyse et Test]]+Tableau3[[#This Row],[HJ Dev]] -> 0
B15: E004 | C15: Production | D15: Gestion des flux | G15: Partiellemnt couvert | R15: 0 | S15: =Tableau3[[#This Row],[HJ Dev]]*(25%+25%) -> 0 | T15: =Tableau3[[#This Row],[HJ Analyse et Test]]+Tableau3[[#This Row],[HJ Dev]] -> 0
B16: E005 | C16: Production | D16: Gestion des OF | G16: Partiellemnt couvert | R16: 0 | S16: =Tableau3[[#This Row],[HJ Dev]]*(25%+25%) -> 0 | T16: =Tableau3[[#This Row],[HJ Analyse et Test]]+Tableau3[[#This Row],[HJ Dev]] -> 0
B17: E006 | C17: Production | D17: Gestion procédures opérationnelles | G17: Partiellemnt couvert | R17: 0 | S17: =Tableau3[[#This Row],[HJ Dev]]*(25%+25%) -> 0 | T17: =Tableau3[[#This Row],[HJ Analyse et Test]]+Tableau3[[#This Row],[HJ Dev]] -> 0
B18: E007 | C18: Production | D18: Ordonnancement | G18: Totalement couvert | R18: 0 | S18: =Tableau3[[#This Row],[HJ Dev]]*(25%+25%) -> 0 | T18: =Tableau3[[#This Row],[HJ Analyse et Test]]+Tableau3[[#This Row],[HJ Dev]] -> 0
C19: Production | D19: Gestion des ressources | G19: Totalement couvert | S19: =Tableau3[[#This Row],[HJ Dev]]*(25%+25%) -> 0 | T19: =Tableau3[[#This Row],[HJ Analyse et Test]]+Tableau3[[#This Row],[HJ Dev]] -> 0
C20: Maintenance | D20: Planificaition maintenance préventive | G20: Partiellemnt couvert | S20: =Tableau3[[#This Row],[HJ Dev]]*(25%+25%) -> 0 | T20: =Tableau3[[#This Row],[HJ Analyse et Test]]+Tableau3[[#This Row],[HJ Dev]] -> 0
C21: Maintenance | D21: Planificaition maintenance Curative | G21: Partiellemnt couvert | S21: =Tableau3[[#This Row],[HJ Dev]]*(25%+25%) -> 0 | T21: =Tableau3[[#This Row],[HJ Analyse et Test]]+Tableau3[[#This Row],[HJ Dev]] -> 0
C22: Maintenance | D22: Surveillance des paramètres machines | G22: Totalement couvert | S22: =Tableau3[[#This Row],[HJ Dev]]*(25%+25%) -> 0 | T22: =Tableau3[[#This Row],[HJ Analyse et Test]]+Tableau3[[#This Row],[HJ Dev]] -> 0
C23: Qualité | D23: Contrôle de la qualité | G23: Partiellemnt couvert | S23: =Tableau3[[#This Row],[HJ Dev]]*(25%+25%) -> 0 | T23: =Tableau3[[#This Row],[HJ Analyse et Test]]+Tableau3[[#This Row],[HJ Dev]] -> 0
C24: Qualité | D24: Gestion de la traçabilité | G24: Partiellemnt couvert | S24: =Tableau3[[#This Row],[HJ Dev]]*(25%+25%) -> 0 | T24: =Tableau3[[#This Row],[HJ Analyse et Test]]+Tableau3[[#This Row],[HJ Dev]] -> 0
C25: Qualité | D25: Gestion des dérogations | G25: Partiellemnt couvert | S25: =Tableau3[[#This Row],[HJ Dev]]*(25%+25%) -> 0 | T25: =Tableau3[[#This Row],[HJ Analyse et Test]]+Tableau3[[#This Row],[HJ Dev]] -> 0
C26: Qualité | D26: Amélioration continue | G26: Partiellemnt couvert | S26: =Tableau3[[#This Row],[HJ Dev]]*(25%+25%) -> 0 | T26: =Tableau3[[#This Row],[HJ Analyse et Test]]+Tableau3[[#This Row],[HJ Dev]] -> 0
C27: Transverse | D27: Gestion des MOD (Main d'œuvre directe) | S27: =Tableau3[[#This Row],[HJ Dev]]*(25%+25%) -> 0 | T27: =Tableau3[[#This Row],[HJ Analyse et Test]]+Tableau3[[#This Row],[HJ Dev]] -> 0
C28: Transverse | D28: Monitoring de la performance | S28: =Tableau3[[#This Row],[HJ Dev]]*(25%+25%) -> 0 | T28: =Tableau3[[#This Row],[HJ Analyse et Test]]+Tableau3[[#This Row],[HJ Dev]] -> 0
C29: Transverse | D29: Gestion des risques | S29: =Tableau3[[#This Row],[HJ Dev]]*(25%+25%) -> 0 | T29: =Tableau3[[#This Row],[HJ Analyse et Test]]+Tableau3[[#This Row],[HJ Dev]] -> 0
D30: Affectation Opérateur/Poste | S30: =Tableau3[[#This Row],[HJ Dev]]*(25%+25%) -> 0 | T30: =Tableau3[[#This Row],[HJ Analyse et Test]]+Tableau3[[#This Row],[HJ Dev]] -> 0
D31: Suivi OF en temps réel | S31: =Tableau3[[#This Row],[HJ Dev]]*(25%+25%) -> 0 | T31: =Tableau3[[#This Row],[HJ Analyse et Test]]+Tableau3[[#This Row],[HJ Dev]] -> 0
D32: Suivi de la matière consommée en Temps réel | S32: =Tableau3[[#This Row],[HJ Dev]]*(25%+25%) -> 0 | T32: =Tableau3[[#This Row],[HJ Analyse et Test]]+Tableau3[[#This Row],[HJ Dev]] -> 0
D33: Webservice Test Qualité SF->LIMS | S33: =Tableau3[[#This Row],[HJ Dev]]*(25%+25%) -> 0 | T33: =Tableau3[[#This Row],[HJ Analyse et Test]]+Tableau3[[#This Row],[HJ Dev]] -> 0
D34: Ordonnancer la réception des matières réceptionnées selon l’état des emplacements de stockage (Silos, Bâtiment) | S34: =Tableau3[[#This Row],[HJ Dev]]*(25%+25%) -> 0 | T34: =Tableau3[[#This Row],[HJ Analyse et Test]]+Tableau3[[#This Row],[HJ Dev]] -> 0
D35: Ordonnancer la préparation des mélanges d’encres | S35: =Tableau3[[#This Row],[HJ Dev]]*(25%+25%) -> 0 | T35: =Tableau3[[#This Row],[HJ Analyse et Test]]+Tableau3[[#This Row],[HJ Dev]] -> 0
D36: Collecter et communiquer l’état de chaque emplacement de stockage (Disponible, Bloqué, en nettoyage, en Maintenance) | S36: =Tableau3[[#This Row],[HJ Dev]]*(25%+25%) -> 0 | T36: =Tableau3[[#This Row],[HJ Analyse et Test]]+Tableau3[[#This Row],[HJ Dev]] -> 0
D37: Collecter et communiquer les paramètres définissant les conditions de stockage (Température, Humidité) | S37: =Tableau3[[#This Row],[HJ Dev]]*(25%+25%) -> 0 | T37: =Tableau3[[#This Row],[HJ Analyse et Test]]+Tableau3[[#This Row],[HJ Dev]] -> 0
D38: Collecter et communiquer les paramètres définissant les conditions d'élevage (température, humidité, luminosité, taux de CO2, dépression) | S38: =Tableau3[[#This Row],[HJ Dev]]*(25%+25%) -> 0 | T38: =Tableau3[[#This Row],[HJ Analyse et Test]]+Tableau3[[#This Row],[HJ Dev]] -> 0
D39: Déclencher automatiquement les processus de réajustement des conditions de stockage (Dépassement de température, dépassement d’humidité) | S39: =Tableau3[[#This Row],[HJ Dev]]*(25%+25%) -> 0 | T39: =Tableau3[[#This Row],[HJ Analyse et Test]]+Tableau3[[#This Row],[HJ Dev]] -> 0
D40: Collecter et communiquer les données sur la quantité stocké (Poids, Alloué pour quel OF, Données qualité, emplacement) | S40: =Tableau3[[#This Row],[HJ Dev]]*(25%+25%) -> 0 | T40: =Tableau3[[#This Row],[HJ Analyse et Test]]+Tableau3[[#This Row],[HJ Dev]] -> 0
D41: Collecter et communiquer la quantité de déchets/ déclassées | S41: =Tableau3[[#This Row],[HJ Dev]]*(25%+25%) -> 0 | T41: =Tableau3[[#This Row],[HJ Analyse et Test]]+Tableau3[[#This Row],[HJ Dev]] -> 0
... D63: Interagir en mode Q&A pour la consultation des documents opérationnels | S63: =Tableau3[[#This Row],[HJ Dev]]*(25%+25%) -> 0 | T63: =Tableau3[[#This Row],[HJ Analyse et Test]]+Tableau3[[#This Row],[HJ Dev]] -> 0
S64: =Tableau3[[#This Row],[HJ Dev]]*(25%+25%) -> 0 | T64: =Tableau3[[#This Row],[HJ Analyse et Test]]+Tableau3[[#This Row],[HJ Dev]] -> 0
S65: =Tableau3[[#This Row],[HJ Dev]]*(25%+25%) -> 0 | T65: =Tableau3[[#This Row],[HJ Analyse et Test]]+Tableau3[[#This Row],[HJ Dev]] -> 0
...

Sheet Feuil1

Sheet Modifs Doc
B3: Gestion Exigences Projet
B5: ='Gestion Exigences'!B5 -> Client | D5: ='Gestion Exigences'!H5 -> La Rose Blanche
B6: ='Gestion Exigences'!B6 -> Projet | D6: ='Gestion Exigences'!H6 -> Digitalisation Groupe
B8: ='Gestion Exigences'!B8 -> Réf Modèle Document | C8: ='Gestion Exigences'!H8 -> MD203
B9: ='Gestion Exigences'!B9 -> Version Modèle Document | C9: ='Gestion Exigences'!H9 -> V1.5
B11: Version | C11: Date | D11: Modifications | E11: Auteur(s) | F11: Vérificateur(s) | G11: Approbateur
B12: V1.0 | C12: 45342 | D12: Version initiale | E12: Nihel K. | F12: Mahdi B. + Ferjania BA | G12: Imed A.

Sheet Params
B2: BU | C2: Nature | D2: Exigence identifiée pendant la phase | E2: Source | F2: Oui/Non | G2: Statut Client | H2: Statut Interne | I2: Catégorie
B3: SE | C3: Fonctionnelle | D3: Commerciale | E3: CdC client | F3: Oui | G3: Validée par le client | H3: Validée | I3: *** SE
B4: SE-TN | C4: Performance | D4: Conception | E4: Workshop/réunion client | F4: Non | G4: Non validée par client | H4: Non validée | I4: SE-Processus
B5: SE-MA | C5: Reglementaire | D5: Réalisation | E5: Workshop/réunion Interne | F5: N/A | G5: N/A | H5: N/A | I5: SE-Mécanique
B6: SF | C6: Sécurité | D6: Mise en œuvre | E6: Standards client | I6: SE-Electrique
B7: R&D | C7: Standard Client | D7: Support et maintenance | E7: Standards ADDIXO | I7: SE-Soft
B8: LOOYAS | C8: Standard ADDIXO | E8: Reglementation | I8: SE-Auto
B9: A définir | E9: Demande modification | I9: SE-Fabrication
I10: SE-Intégration
I11: SE-Achats
I13: *** SF
I14: SF-Processus
I15: SF-Fonctionnelle
I16: SF-Connectivité Machine
I17: SF-Intégration SI
I18: SF-Software
I19: SF-Infra IT
I21: *** TC
I22: TC-Prestations sur site client
