Workbook

Sheet Fiche Client
B6: Client
B7: Secteur
B8: Nombre de ligne de production
B9: Nombre de machine
B10: Nombre de poste manuel

Sheet Gestion Exigences
B2: Gestion Exigences Projet | N2: Chiffrage Réalisation (SF only) | Q2: Revue et Vérification Pendant la Conception
B4: BU | D4: SF
B5: Client | D5: PEC AC
B6: Projet | D6: Digitalisation PEC AC
B7: Réf BPA du Devis | D7: S0-00xyz | G7: Zone de saisie
B8: Réf BPA du Projet | D8: PR-22-0xyz
B10: Réf Modèle Document | D10: MD203 | I10: Confidentiel | Usage Client Limité
B11: Version Modèle Document | D11: V1.5
B13: ID | C13: Intitulé Exigence | D13: Nature | E13: Catégorie | F13: Exigence idenfiée pendant la phase | G13: Description de l'exigence | H13: Source | I13: Desciption de la solution MOMSOFT | J13: Ecart entre exigence client et la solution proposée - préciser aussi les limites et hypothèses si applicable | K13: Validation Interne | L13: Validation Interne par: | M13: Statut Client | N13: HJ Dev | O13: HJ Analyse et Test | P13: Total HJ | Q13: Description comment la conception de la solution prend en compte l'exigence client | R13: Conception réalisée par: | S13: Revue conception réalisée par | T13: Vérification de la conception réalisée par | U13: Preuve de vérification | V13: Notes
B14: E001 | C14: Gérer plusieurs Sites | N14: 3 | O14: =Tableau3[[#This Row],[HJ Dev]]*(25%+25%) -> 1.5 | P14: =Tableau3[[#This Row],[HJ Analyse et Test]]+Tableau3[[#This Row],[HJ Dev]] -> 4.5 | Q14: N/A | R14: N/A | S14: N/A | T14: N/A | U14: N/A
B15: E006 | C15: Gérer les familles de produit | N15: 0 | O15: =Tableau3[[#This Row],[HJ Dev]]*(25%+25%) -> 0 | P15: =Tableau3[[#This Row],[HJ Analyse et Test]]+Tableau3[[#This Row],[HJ Dev]] -> 0
B16: E007 | C16: Gérer les sous familles de produit | N16: 0 | O16: =Tableau3[[#This Row],[HJ Dev]]*(25%+25%) -> 0 | P16: =Tableau3[[#This Row],[HJ Analyse et Test]]+Tableau3[[#This Row],[HJ Dev]] -> 0
B17: E008 | C17: Gérer des catégories de produit | O17: =Tableau3[[#This Row],[HJ Dev]]*(25%+25%) -> 0 | P17: =Tableau3[[#This Row],[HJ Analyse et Test]]+Tableau3[[#This Row],[HJ Dev]] -> 0
B18: E009 | C18: Déclarer la production par Lot | O18: =Tableau3[[#This Row],[HJ Dev]]*(25%+25%) -> 0 | P18: =Tableau3[[#This Row],[HJ Analyse et Test]]+Tableau3[[#This Row],[HJ Dev]] -> 0
B19: E010 | C19: Déclarer la production par Palette | O19: =Tableau3[[#This Row],[HJ Dev]]*(25%+25%) -> 0 | P19: =Tableau3[[#This Row],[HJ Analyse et Test]]+Tableau3[[#This Row],[HJ Dev]] -> 0
B20: E011 | C20: Déclarer la production par caisse | O20: =Tableau3[[#This Row],[HJ Dev]]*(25%+25%) -> 0 | P20: =Tableau3[[#This Row],[HJ Analyse et Test]]+Tableau3[[#This Row],[HJ Dev]] -> 0
B21: E012 | C21: Gérer les OF | O21: =Tableau3[[#This Row],[HJ Dev]]*(25%+25%) -> 0 | P21: =Tableau3[[#This Row],[HJ Analyse et Test]]+Tableau3[[#This Row],[HJ Dev]] -> 0
B22: E013 | C22: Gérer les fiches de démarrage | O22: =Tableau3[[#This Row],[HJ Dev]]*(25%+25%) -> 0 | P22: =Tableau3[[#This Row],[HJ Analyse et Test]]+Tableau3[[#This Row],[HJ Dev]] -> 0
B23: E014 | C23: Gérer les fiches de suivi | O23: =Tableau3[[#This Row],[HJ Dev]]*(25%+25%) -> 0 | P23: =Tableau3[[#This Row],[HJ Analyse et Test]]+Tableau3[[#This Row],[HJ Dev]] -> 0
B24: E015 | C24: Gérer les commandes | O24: =Tableau3[[#This Row],[HJ Dev]]*(25%+25%) -> 0 | P24: =Tableau3[[#This Row],[HJ Analyse et Test]]+Tableau3[[#This Row],[HJ Dev]] -> 0
B25: E016 | C25: MSP | O25: =Tableau3[[#This Row],[HJ Dev]]*(25%+25%) -> 0 | P25: =Tableau3[[#This Row],[HJ Analyse et Test]]+Tableau3[[#This Row],[HJ Dev]] -> 0
B26: E017 | C26: QRQC | O26: =Tableau3[[#This Row],[HJ Dev]]*(25%+25%) -> 0 | P26: =Tableau3[[#This Row],[HJ Analyse et Test]]+Tableau3[[#This Row],[HJ Dev]] -> 0
B27: E018 | C27: 6S | O27: =Tableau3[[#This Row],[HJ Dev]]*(25%+25%) -> 0 | P27: =Tableau3[[#This Row],[HJ Analyse et Test]]+Tableau3[[#This Row],[HJ Dev]] -> 0
B28: E019 | C28: Gestion de stock | O28: =Tableau3[[#This Row],[HJ Dev]]*(25%+25%) -> 0 | P28: =Tableau3[[#This Row],[HJ Analyse et Test]]+Tableau3[[#This Row],[HJ Dev]] -> 0
... B32: E023 | C32: Tableau de bord | O32: =Tableau3[[#This Row],[HJ Dev]]*(25%+25%) -> 0 | P32: =Tableau3[[#This Row],[HJ Analyse et Test]]+Tableau3[[#This Row],[HJ Dev]] -> 0
B33: E024 | O33: =Tableau3[[#This Row],[HJ Dev]]*(25%+25%) -> 0 | P33: =Tableau3[[#This Row],[HJ Analyse et Test]]+Tableau3[[#This Row],[HJ Dev]] -> 0
B34: E025 | C34: Configuration des opérations ( artcile et sous articles) | O34: =Tableau3[[#This Row],[HJ Dev]]*(25%+25%) -> 0 | P34: =Tableau3[[#This Row],[HJ Analyse et Test]]+Tableau3[[#This Row],[HJ Dev]] -> 0
B35: E026 | C35: Gestion des opérations | G35: suivi des temps opératoires , prod et qualité par opération | O35: =Tableau3[[#This Row],[HJ Dev]]*(25%+25%) -> 0 | P35: =Tableau3[[#This Row],[HJ Analyse et Test]]+Tableau3[[#This Row],[HJ Dev]] -> 0
B36: E027 | C36: Suivi performance par opérateur | O36: =Tableau3[[#This Row],[HJ Dev]]*(25%+25%) -> 0 | P36: =Tableau3[[#This Row],[HJ Analyse et Test]]+Tableau3[[#This Row],[HJ Dev]] -> 0
B37: E028 | C37: Inétgartion des OF de tous les sites PEC | O37: =Tableau3[[#This Row],[HJ Dev]]*(25%+25%) -> 0 | P37: =Tableau3[[#This Row],[HJ Analyse et Test]]+Tableau3[[#This Row],[HJ Dev]] -> 0
B38: E029 | C38: Module qualité | O38: =Tableau3[[#This Row],[HJ Dev]]*(25%+25%) -> 0 | P38: =Tableau3[[#This Row],[HJ Analyse et Test]]+Tableau3[[#This Row],[HJ Dev]] -> 0
B39: E030 | C39: gestion des sites | O39: =Tableau3[[#This Row],[HJ Dev]]*(25%+25%) -> 0 | P39: =Tableau3[[#This Row],[HJ Analyse et Test]]+Tableau3[[#This Row],[HJ Dev]] -> 0
B40: E031 | O40: =Tableau3[[#This Row],[HJ Dev]]*(25%+25%) -> 0 | P40: =Tableau3[[#This Row],[HJ Analyse et Test]]+Tableau3[[#This Row],[HJ Dev]] -> 0
B41: E032 | O41: =Tableau3[[#This Row],[HJ Dev]]*(25%+25%) -> 0 | P41: =Tableau3[[#This Row],[HJ Analyse et Test]]+Tableau3[[#This Row],[HJ Dev]] -> 0
B42: E033 | O42: =Tableau3[[#This Row],[HJ Dev]]*(25%+25%) -> 0 | P42: =Tableau3[[#This Row],[HJ Analyse et Test]]+Tableau3[[#This Row],[HJ Dev]] -> 0
B43: E034 | O43: =Tableau3[[#This Row],[HJ Dev]]*(25%+25%) -> 0 | P43: =Tableau3[[#This Row],[HJ Analyse et Test]]+Tableau3[[#This Row],[HJ Dev]] -> 0
B44: E035 | O44: =Tableau3[[#This Row],[HJ Dev]]*(25%+25%) -> 0 | P44: =Tableau3[[#This Row],[HJ Analyse et Test]]+Tableau3[[#This Row],[HJ Dev]] -> 0
B45: E036 | O45: =Tableau3[[#This Row],[HJ Dev]]*(25%+25%) -> 0 | P45: =Tableau3[[#This Row],[HJ Analyse et Test]]+Tableau3[[#This Row],[HJ Dev]] -> 0
B46: E037 | O46: =Tableau3[[#This Row],[HJ Dev]]*(25%+25%) -> 0 | P46: =Tableau3[[#This Row],[HJ Analyse et Test]]+Tableau3[[#This Row],[HJ Dev]] -> 0
B47: E038 | O47: =Tableau3[[#This Row],[HJ Dev]]*(25%+25%) -> 0 | P47: =Tableau3[[#This Row],[HJ Analyse et Test]]+Tableau3[[#This Row],[HJ Dev]] -> 0
...

Sheet Modifs Doc
B3: Gestion Exigences Projet
B5: ='Gestion Exigences'!B5 -> Client | D5: ='Gestion Exigences'!D5 -> PEC AC
B6: ='Gestion Exigences'!B6 -> Projet | D6: ='Gestion Exigences'!D6 -> Digitalisation PEC AC
B7: ='Gestion Exigences'!B7 -> Réf BPA du Devis | D7: ='Gestion Exigences'!D7 -> S0-00xyz
B8: ='Gestion Exigences'!B8 -> Réf BPA du Projet | D8: ='Gestion Exigences'!D8 -> PR-22-0xyz
B10: ='Gestion Exigences'!B10 -> Réf Modèle Document | C10: ='Gestion Exigences'!D10 -> MD203
B11: ='Gestion Exigences'!B11 -> Version Modèle Document | C11: ='Gestion Exigences'!D11 -> V1.5
B13: Version | C13: Date | D13: Modifications | E13: Auteur(s) | F13: Vérificateur(s) | G13: Approbateur
B14: V1.0 | C14: 45342 | D14: Version initiale | E14: Nihel K. | F14: Mahdi B. + Ferjania BA | G14: Imed A.
B15: V1.1 | C15: 45701 | D15: Adaptation des paramètres et du logo | E15: Moatez D. | F15: Mahdi B. | G15: Imed A.
B16: V1.2 | C16: 45786 | D16: Adaptation du logo | E16: Moatez D. | F16: Mahdi B. | G16: Imed A.

Sheet Params
B2: BU | C2: Nature | D2: Exigence identifiée pendant la phase | E2: Source | F2: Oui/Non | G2: Statut Client | H2: Statut Interne | I2: Catégorie
B3: SF | C3: Fonctionnelle | D3: Commerciale | E3: CdC client | F3: Oui | G3: Validée par le client | H3: Validée | I3: *** SF
B4: R&D | C4: Performance | D4: Conception | E4: Workshop/réunion client | F4: Non | G4: Non validée par client | H4: Non validée | I4: SF-Processus
B5: A définir | C5: Reglementaire | D5: Réalisation | E5: Workshop/réunion Interne | F5: N/A | G5: N/A | H5: N/A | I5: SF-Fonctionnelle
B6: A définir | C6: Sécurité | D6: Mise en œuvre | E6: Standards client | I6: SF-Connectivité Machine
C7: Standard Client | D7: Support et maintenance | E7: Standards MOMSOFT | I7: SF-Intégration SI
C8: Standard MOMSOFT | E8: Reglementation | I8: SF-Software
E9: Demande modification | I9: SF-Infra IT
I11: *** TC
I12: TC-Prestations sur site client
