Workbook

Sheet Fiche Client
B6: Client
B7: Secteur
B8: Nombre de ligne de production
B9: Nombre de machine
B10: Nombre de poste manuel

Sheet Gestion Exigences
B2: Gestion Exigences Projet | N2: Chiffrage Réalisation (SF only) | Q2: Revue et Vérification Pendant la Conception
B4: BU | D4: SF
B5: Client | D5: SIAM
B6: Projet | D6: Digitalisation Usine
B7: Réf BPA du Devis | D7: S0-00xyz | G7: Zone de saisie
B8: Réf BPA du Projet | D8: PR-22-0xyz
B10: Réf Modèle Document | D10: MD203 | I10: Confidentiel | Usage Client Limité
B11: Version Modèle Document | D11: V1.5
B13: ID | C13: Intitulé Exigence | D13: Nature | E13: Catégorie | F13: Exigence idenfiée pendant la phase | G13: Description de l'exigence | H13: Source | I13: Desciption de la solution MOMSOFT | J13: Ecart entre exigence client et la solution proposée - préciser aussi les limites et hypothèses si applicable | K13: Validation Interne | L13: Validation Interne par: | M13: Statut Client | N13: HJ Dev | O13: HJ Analyse et Test | P13: Total HJ | Q13: Description comment la conception de la solution prend en compte l'exigence client | R13: Conception réalisée par: | S13: Revue conception réalisée par | T13: Vérification de la conception réalisée par | U13: Preuve de vérification | V13: Notes
B14: E001 | C14: Configuration des données | D14: Fonctionnelle | E14: SF-Fonctionnelle | F14: Commerciale | G14: Configuration complète et gestion de l'usine | H14: Workshop/réunion client | I14: Standard | J14: La solution offre un Module Core permettant la modélisation, gestion et planification pour une usine connectée: -Modélisation hiérarchique de l'usine: Sites, ateliers, lignes, postes, machines. -Gestion des produits. -Gestion des incidents et défauts: Pannes par machines, défauts par produit. -Gestion des utilisateurs et des autorisations: Rôles et accès contrôlés. -Gestion des équipes: Production, qualité, maintenance. -Planification des lignes et des équipes: Cycles, équipes, calendrier de travail. -Configuration de l'outillage: Moules, gabarits.. | K14: RAS | L14: Mahdi B. | M14: Validée par le client | N14: 0 | O14: =Tableau3[[#This Row],[HJ Dev]]*(25%+25%) -> 0 | P14: =Tableau3[[#This Row],[HJ Analyse et Test]]+Tableau3[[#This Row],[HJ Dev]] -> 0 | Q14: N/A | R14: N/A | S14: N/A | T14: N/A | U14: N/A
B15: E002 | C15: Chargement des données | D15: Fonctionnelle | E15: SF-Intégration SI | F15: Commerciale | G15: Automatisation de l'importation de données dans la solution | H15: Workshop/réunion client | I15: Standard | J15: La solution comprend un module "Intégartion SI" permettant l'intégration automatisée de données: Chargement automatique de données depuis des fichiers CSV ou des systèmes d'information clients. En supportant les entités produits, utilisateurs et outillages, avec une gestion détaillée des erreurs d'intégration. | K15: RAS | L15: Mahdi B. | M15: Validée par le client | N15: 0 | O15: =Tableau3[[#This Row],[HJ Dev]]*(25%+25%) -> 0 | P15: =Tableau3[[#This Row],[HJ Analyse et Test]]+Tableau3[[#This Row],[HJ Dev]] -> 0 | Q15: N/A | R15: N/A | S15: N/A | T15: N/A | U15: N/A
B16: E003 | C16: Chargement des produits à partir de l'ERP. | D16: Fonctionnelle | E16: SF-Intégration SI | F16: Commerciale | G16: Chargement des produits à partir de l'ERP. | H16: Workshop/réunion client | I16: Lecture des produits à partir de l'ERP. | J16: Adaptation : -Créer une méthode de chargement des produits selon un modèle standard de SF | K16: RAS | L16: Mahdi B. | M16: Validée par le client | N16: 1.5 | O16: =Tableau3[[#This Row],[HJ Dev]]*(25%+25%) -> 0.75 | P16: =Tableau3[[#This Row],[HJ Analyse et Test]]+Tableau3[[#This Row],[HJ Dev]] -> 2.25
B17: E004 | C17: Chargement des pannes à partir de l'ERP. | D17: Fonctionnelle | E17: SF-Intégration SI | F17: Commerciale | G17: Chargement des pannes à partir de l'ERP. | H17: Workshop/réunion client | I17: Lecture des pannes depuis l’ERP. | J17: Adaptation : -Créer une méthode de chargement des pannes selon le modèle standard de SF. | K17: RAS | L17: Mahdi B. | M17: Validée par le client | N17: 1 | O17: =Tableau3[[#This Row],[HJ Dev]]*(25%+25%) -> 0.5 | P17: =Tableau3[[#This Row],[HJ Analyse et Test]]+Tableau3[[#This Row],[HJ Dev]] -> 1.5
B18: E005 | C18: Chargement des incidents qualité à partir de l'ERP. | D18: Fonctionnelle | E18: SF-Intégration SI | F18: Commerciale | G18: Chargement des incidents qualité depuis l’ERP. | H18: Workshop/réunion client | I18: Lecture des incidents qualité depuis l’ERP. | J18: Adaptation : -Créer une méthode de chargement des incidents qualité selon le modèle standard de SF. | K18: RAS | L18: Mahdi B. | M18: Validée par le client | N18: 1.5 | O18: =Tableau3[[#This Row],[HJ Dev]]*(25%+25%) -> 0.75 | P18: =Tableau3[[#This Row],[HJ Analyse et Test]]+Tableau3[[#This Row],[HJ Dev]] -> 2.25
B19: E006 | C19: Chargement des moules à partir de l'ERP. | D19: Fonctionnelle | E19: SF-Intégration SI | F19: Commerciale | G19: Chargement des moules depuis l’ERP. | H19: Workshop/réunion client | I19: Lecture des moules depuis l’ERP. | J19: Adaptation : -Créer une méthode de chargement des moules selon le modèle standard de SF. | K19: RAS | L19: Mahdi B. | M19: Validée par le client | N19: 1 | O19: =Tableau3[[#This Row],[HJ Dev]]*(25%+25%) -> 0.5 | P19: =Tableau3[[#This Row],[HJ Analyse et Test]]+Tableau3[[#This Row],[HJ Dev]] -> 1.5
B20: E007 | C20: Chargement des utilisateurs à partir de l'ERP. | D20: Fonctionnelle | E20: SF-Intégration SI | F20: Commerciale | G20: Chargement des utilisateurs depuis l’ERP. | H20: Workshop/réunion client | I20: Lecture des utilisateurs depuis l’ERP. | J20: Adaptation : -Créer une méthode de chargement des utilisateurs selon le modèle standard de SF. | K20: RAS | L20: Mahdi B. | M20: Validée par le client | N20: 1 | O20: =Tableau3[[#This Row],[HJ Dev]]*(25%+25%) -> 0.5 | P20: =Tableau3[[#This Row],[HJ Analyse et Test]]+Tableau3[[#This Row],[HJ Dev]] -> 1.5
B21: E008 | C21: Chargement de la nomenclature à partir de l'ERP . | D21: Fonctionnelle | E21: SF-Intégration SI | F21: Commerciale | G21: Chargement de la nomenclature de l'ERP . | H21: Workshop/réunion client | I21: Lecture de la nomenclature produit à partir de l'ERP. | J21: Adaptation : - Créer une méthode de chargement de la nomenclature selon un modèle standard de SF | K21: RAS | L21: Mahdi B. | M21: Validée par le client | N21: 2 | O21: =Tableau3[[#This Row],[HJ Dev]]*(25%+25%) -> 1 | P21: =Tableau3[[#This Row],[HJ Analyse et Test]]+Tableau3[[#This Row],[HJ Dev]] -> 3 | Q21: N/A | R21: N/A | S21: N/A | T21: N/A | U21: N/A
B22: E009 | C22: Chargement de la gamme opératoire par produit à partir de l'ERP . | D22: Fonctionnelle | E22: SF-Intégration SI | F22: Commerciale | G22: Chargement de la gamme par produit apartir de l'ERP . | H22: Workshop/réunion client | I22: Lecture de la gamme opératoire par produit à partir de l'ERP. | J22: Adaptation : - Créer une méthode de chargement de la gamme opératoire selon le modéle standard de SF . | K22: RAS | L22: Mahdi B. | M22: Validée par le client | N22: 1 | O22: =Tableau3[[#This Row],[HJ Dev]]*(25%+25%) -> 0.5 | P22: =Tableau3[[#This Row],[HJ Analyse et Test]]+Tableau3[[#This Row],[HJ Dev]] -> 1.5 | Q22: N/A | R22: N/A | S22: N/A | T22: N/A | U22: N/A
B23: E010 | C23: Gestion de la nomenclature | D23: Fonctionnelle | E23: SF-Fonctionnelle | F23: Commerciale | G23: Permettre la gestion de la nomenclature | H23: Workshop/réunion client | I23: Ajout d'une interface pour la gestion de la nomenclature | J23: Adaptation : - Ajout d'une interface qui permet la création, la modification et la suppression de la nomenclature. | K23: RAS | L23: Mahdi B. | M23: Validée par le client | N23: 1 | O23: =Tableau3[[#This Row],[HJ Dev]]*(25%+25%) -> 0.5 | P23: =Tableau3[[#This Row],[HJ Analyse et Test]]+Tableau3[[#This Row],[HJ Dev]] -> 1.5 | Q23: N/A | R23: N/A | S23: N/A | T23: N/A | U23: N/A
B24: E011 | C24: Gestion de la gamme opératoire | D24: Fonctionnelle | E24: SF-Fonctionnelle | F24: Commerciale | G24: Permettre la gestion de la gamme opératoire | H24: Workshop/réunion client | I24: Ajout d'une interface pour la gestion de la gamme opératoire | J24: Adaptation : - Ajout d'une interface qui permet la création, la modification et la suppression de la gamme opératoire - La gamme opératoire est sous forme d'un tableau permettant de définir l'ordre des opérations et de modifier leurs paramétres si besoin | K24: RAS | L24: Mahdi B. | M24: Validée par le client | N24: 2 | O24: =Tableau3[[#This Row],[HJ Dev]]*(25%+25%) -> 1 | P24: =Tableau3[[#This Row],[HJ Analyse et Test]]+Tableau3[[#This Row],[HJ Dev]] -> 3 | Q24: N/A | R24: N/A | S24: N/A | T24: N/A | U24: N/A
B25: E012 | C25: Chargement des OF planifiés à partir de l'ERP. | D25: Fonctionnelle | E25: SF-Intégration SI | F25: Commerciale | G25: Chargement des OF planifiés "fermes" à partir de l'ERP à travers webservices . | H25: Workshop/réunion client | I25: Lecture des OF planifiés "fermes" à travers webservices. | J25: Adaptation webservice de chargement des OF planifiés à partir de l'ERP. Cette exigence nécessite un travail de collaboration entre l'équipe MOMSOFT et l'équipe ERP. | K25: RAS | L25: Mahdi B. | M25: Validée par le client | N25: 1 | O25: =Tableau3[[#This Row],[HJ Dev]]*(25%+25%) -> 0.5 | P25: =Tableau3[[#This Row],[HJ Analyse et Test]]+Tableau3[[#This Row],[HJ Dev]] -> 1.5 | Q25: N/A | R25: N/A | S25: N/A | T25: N/A | U25: N/A
B26: E013 | C26: Gestion et suivi des ordres de fabrications | D26: Fonctionnelle | E26: SF-Fonctionnelle | F26: Commerciale | G26: Gérer et suivre les ordres de fabrications | H26: Workshop/réunion client | I26: Standard | J26: La solution offre une interface "Gestion des OF" sous le module "Production" permettant : - Ajout manuel des Ordres de fabrication en spécifiant les informations associées nécessaires : Atelier , ligne , commande , produit , temps de cycle , quantité objectif , temps de changement de série , matière . - Gestion centralisée des OF: Gestion et suivi des différents statuts des OF (planifié, lancé, suspendu, changement de série, etc.) Mise à jour en temps réel des statuts Workflow de validation des changements de statut paramétrables - Gestion des opérations associées à un OF: Calcul des dates de début et fin prévues pour chaque opération Suivi d'avancement des opérations - Planification et ajustement : Planification initiale des OF en fonction des données saisies Ajustement de la planification en cas d'aléas Consultation en temps réel de l'impact des ajustements sur la planification globale. | K26: RAS | L26: Mahdi B. | M26: Validée par le client | N26: 0 | O26: =Tableau3[[#This Row],[HJ Dev]]*(25%+25%) -> 0 | P26: =Tableau3[[#This Row],[HJ Analyse et Test]]+Tableau3[[#This Row],[HJ Dev]] -> 0 | Q26: N/A | R26: N/A | S26: N/A | T26: N/A | U26: N/A
B27: E014 | C27: Gestion et suivi des opérations | D27: Fonctionnelle | E27: SF-Fonctionnelle | F27: Commerciale | G27: Permettre la gestion et le suivi des opérations. | H27: Workshop/réunion client | I27: Ajout d'une interface pour la gestion des opérations. | J27: Adaptation : Ajout d'une interface " gestion des opérations " permettant : -Gestion des opération par OF ( création, modification et suppression ) -Gestion et suivi des statuts des opérations (planifié, lancé, suspendu.) | K27: RAS | L27: Mahdi B. | M27: Validée par le client | N27: 3 | O27: =Tableau3[[#This Row],[HJ Dev]]*(25%+25%) -> 1.5 | P27: =Tableau3[[#This Row],[HJ Analyse et Test]]+Tableau3[[#This Row],[HJ Dev]] -> 4.5 | Q27: N/A | R27: N/A | S27: N/A | T27: N/A | U27: N/A
B28: E015 | C28: Gestion et suivi de production par opération | D28: Fonctionnelle | E28: SF-Fonctionnelle | F28: Commerciale | G28: Permettre la gestion de production des opérations | H28: Workshop/réunion client | I28: Ajout d'une interface pour la gestion de production des opérations | J28: Adaptation : Ajout d'une interface assurant les fonctionnalités suivantes : - Déclaration de production par opération et par OF : quantités conformes, non conformes, rebutées et en retouche (rework). - Suivi des opérations liées à un OF, incluant : Mise à jour en temps réel des statuts Le calcul des dates de début et de fin prévues pour chaque opération. Le suivi de l’avancement des opérations. -L’opération est représentée sous forme d’un tableau contenant les champs suivants : Temps opératoire Temps de réglage Temps d’attente (avant et après) Quantité produite Quantité OK Quantité NOK Rework Quantité rebutée | K28: RAS | L28: Mahdi B. | M28: Validée par le client | N28: 3.5 | O28: =Tableau3[[#This Row],[HJ Dev]]*(25%+25%) -> 1.75 | P28: =Tableau3[[#This Row],[HJ Analyse et Test]]+Tableau3[[#This Row],[HJ Dev]] -> 5.25
B29: E016 | C29: Gestion et suivi de la prodution par OF | D29: Fonctionnelle | E29: SF-Fonctionnelle | F29: Commerciale | G29: Déclaration manuelle et automatique de la production et des non-conformité et des arrêts en assurant un suivi en temps réel et un historique détaillé. | H29: Workshop/réunion client | I29: Standard | J29: La solution comprend un module de "Gestion de Production" offrant les fonctionnalités suivantes : -Déclaration manuelle et automatiques de la production : Enregistrement des quantités produites et des non-conformités pour chaque Ordre de Fabrication (OF), ligne, et produit. avec la possibilité de la déclaration par lot. -Validation des déclarations :Workflow de validation des déclarations de production avec des niveaux de validation paramétrables -Rapports détaillés : Accès à des rapports détaillés sur l'historique de production, incluant les quantités produites, les non-conformités, ainsi que les performances des lignes et des opérateurs. -Filtrage avancé : Possibilité de filtrer les données par OF, équipe, ligne, produit, et période de production. | K29: RAS | L29: Mahdi B. | M29: Validée par le client | N29: 0 | O29: =Tableau3[[#This Row],[HJ Dev]]*(25%+25%) -> 0 | P29: =Tableau3[[#This Row],[HJ Analyse et Test]]+Tableau3[[#This Row],[HJ Dev]] -> 0
B30: E018 | C30: Intégration ligne de production | D30: Fonctionnelle | E30: SF-Connectivité Machine | F30: Commerciale | G30: Récupération des données machine (paramétres machine, quantités produites, alertes et alarmes). | H30: Workshop/réunion client | I30: Adaptation | J30: Récupération des données de production comprenant les paramètres machines, les quantités produites et non conformes, ainsi que les arrêts et alarmes. | K30: RAS | L30: Mahdi B. | M30: Validée par le client | O30: =Tableau3[[#This Row],[HJ Dev]]*(25%+25%) -> 0 | P30: =Tableau3[[#This Row],[HJ Analyse et Test]]+Tableau3[[#This Row],[HJ Dev]] -> 0
B31: E019 | C31: Historique des paramètres machines | D31: Fonctionnelle | E31: SF-Fonctionnelle | F31: Commerciale | G31: Suivi et historisation des paramètres machines. | H31: Workshop/réunion client | I31: Ajouter une interface assurant la surveillance en temps réel des paramètres machines et l’historisation des données. | J31: Ajouter une interface assuant : -Le suivi en temps réel des paramètres machines. -L’historisation des paramètres machines par produit et par OF. -L’exportation des historiques. | K31: RAS | L31: Mahdi B. | M31: Validée par le client | N31: 2 | O31: =Tableau3[[#This Row],[HJ Dev]]*(25%+25%) -> 1 | P31: =Tableau3[[#This Row],[HJ Analyse et Test]]+Tableau3[[#This Row],[HJ Dev]] -> 3
B32: E020 | C32: Suivi en temps réel | D32: Fonctionnelle | E32: SF-Fonctionnelle | F32: Commerciale | G32: Suivi en temps réel des KPIs | H32: Workshop/réunion client | I32: Standard | J32: La solution offre une supervision de production en temps réel avec le module "Vue 360°" permettant de : -Visualiser l'état des lignes en temps réel avec codification couleur paramétrable.-Suivire des indicateurs clés de performance (KPI): TRS équipe et OF ,Taux de performance, disponibilité et qualité , PPM (pièces par million) -Suivre de la progression des OF. -Analyser des arrêts: Durées, causes et nombre d'occurrences. -Visualiser la production et non-conformité en temps réel: Production totale et horaire par équipe , Non-conformité totale et horaire par équipe avec catégorisation par défaut qualité. | K32: RAS | L32: Mahdi B. | M32: Validée par le client | N32: 0 | O32: =Tableau3[[#This Row],[HJ Dev]]*(25%+25%) -> 0 | P32: =Tableau3[[#This Row],[HJ Analyse et Test]]+Tableau3[[#This Row],[HJ Dev]] -> 0
B33: E021 | C33: Tableau de bord production | D33: Fonctionnelle | E33: SF-Fonctionnelle | F33: Commerciale | G33: Analyser la performance historique des lignes de production Analyser l'évolution des indicateurs clés au cours du temps pour chaque ligne de production. | H33: Workshop/réunion client | I33: Standard | J33: la solution offre un tableau de bord fournissant une vue multi-niveaux de la production en utilisant des indicateurs comme TRS, Quantité produite vs Quantité planifiée, Temps d'arrêt vs temps de production, etc. | K33: RAS | L33: Mahdi B. | M33: Validée par le client | N33: 0 | O33: =Tableau3[[#This Row],[HJ Dev]]*(25%+25%) -> 0 | P33: =Tableau3[[#This Row],[HJ Analyse et Test]]+Tableau3[[#This Row],[HJ Dev]] -> 0
B34: E022 | C34: Gestion des reworks | D34: Fonctionnelle | E34: SF-Fonctionnelle | F34: Commerciale | G34: Permettre la gestion des quantités à traiter et à rebuter | H34: Workshop/réunion client | I34: Ajouter une interface pour la gestion des reworks et des rebuts | J34: Ajouter une interface qui permet: -La gestion des fiches des reworks par opération par OF -La qualification des piéces ( Conforme / Rebut ) | K34: RAS | L34: Mahdi B. | M34: Validée par le client | N34: 1 | O34: =Tableau3[[#This Row],[HJ Dev]]*(25%+25%) -> 0.5 | P34: =Tableau3[[#This Row],[HJ Analyse et Test]]+Tableau3[[#This Row],[HJ Dev]] -> 1.5
B35: E023 | C35: Validation process | D35: Fonctionnelle | E35: SF-Fonctionnelle | F35: Commerciale | G35: Veiller au remplissage des fiches de démarrage, qualité, suivi, ainsi que des fiches BT moule et BT matière pour garantir le bon déroulement de la production. | H35: Workshop/réunion client | I35: Adaptation | J35: Rendre l'obligation de remplissage des fiches de production ( fiches de démarrage, qualité, suivi, ainsi que des fiches BT moule et BT matière ) selon le shift. | K35: RAS | L35: Mahdi B. | M35: Validée par le client | N35: 1.5 | O35: =Tableau3[[#This Row],[HJ Dev]]*(25%+25%) -> 0.75 | P35: =Tableau3[[#This Row],[HJ Analyse et Test]]+Tableau3[[#This Row],[HJ Dev]] -> 2.25
B36: E024 | C36: Fiche de passation | D36: Fonctionnelle | E36: SF-Fonctionnelle | F36: Commerciale | G36: Permettre la gestion de passation entre les postes de production | H36: Workshop/réunion client | I36: Adaptation | J36: Ajouter une interface permettant : -La gestion et l’historisation des fiches de passation. -La création automatique d'une fiche de passation pour chaque shift. -La transmition des opérations d’un poste à un autre aprés remplissage et validation. | K36: RAS | L36: Mahdi B. | M36: Validée par le client | N36: 1.5 | O36: =Tableau3[[#This Row],[HJ Dev]]*(25%+25%) -> 0.75 | P36: =Tableau3[[#This Row],[HJ Analyse et Test]]+Tableau3[[#This Row],[HJ Dev]] -> 2.25
B37: E025 | C37: Fiche alerte | D37: Fonctionnelle | E37: SF-Fonctionnelle | F37: Commerciale | G37: Déclaration des non-conformités identifiées par le responsable de transfert dans la zone de passage vers le stock PF. | H37: Workshop/réunion client | I37: Adaptation | J37: Ajouter une interface permettant : -La gestion et l’historisation des fiches d’alerte. -La notification des responsables qualité lors de la création d’une fiche d’alerte. | K37: RAS | L37: Mahdi B. | M37: Validée par le client | N37: 1.5 | O37: =Tableau3[[#This Row],[HJ Dev]]*(25%+25%) -> 0.75 | P37: =Tableau3[[#This Row],[HJ Analyse et Test]]+Tableau3[[#This Row],[HJ Dev]] -> 2.25
B38: E026 | C38: Fiche non conformité | D38: Fonctionnelle | E38: SF-Fonctionnelle | F38: Commerciale | G38: Déclaration des non-conformités détectées par l'opérateur/ contrôleur qualité et leur validation par le responsable qualité. | H38: Workshop/réunion client | I38: Standard | J38: La solution propose une interface "Fiche Non-Conformité" pour identifier, documenter, analyser et résoudre les incidents de qualité en production, avec les fonctionnalités suivantes : -Identification du problème : Tracer la pièce concernée, ajouter une photo et l’associer à la fiche. Définir le lieu de détection, le type de défaut, et la quantité affectée,Analyser les causes racines (QQCQ), Indiquer le statut du produit (isolé, livré, bloqué). -Actions immédiates :Définir les actions correctives, Décider si le produit sera livré après correction ou nécessite un traitement supplémentaire, Fournir une description complète de la non-conformité. -Analyse des causes :Utiliser les méthodologies 5M (Ishikawa) et 5 Pourquoi. -Actions définitives :Élaborer un plan pour traiter les causes profondes et prévenir la récurrence. Attribuer les responsabilités, informer les parties concernées, et planifier les dates d'exécution. -Historique et consultation :Maintenir un référentiel centralisé des fiches de non-conformité | K38: RAS | L38: Mahdi B. | M38: Validée par le client | N38: 0 | O38: =Tableau3[[#This Row],[HJ Dev]]*(25%+25%) -> 0 | P38: =Tableau3[[#This Row],[HJ Analyse et Test]]+Tableau3[[#This Row],[HJ Dev]] -> 0
B39: E027 | C39: Analyse des causes des non-conformités avec l'outil QRQC | D39: Fonctionnelle | E39: SF-Fonctionnelle | F39: Commerciale | G39: Suivi et analyses des causes des non-conformités avec l'outil QRQC | H39: Workshop/réunion client | I39: Standard | J39: la solution offre un QRQC qui permet de rédoudre les non conformité en déclenchant la création des fiches en s'appuyant sur des seuils de qualité paramètrable , permettant ainsi: -D'idententifier le problème et le contexte de l'incident -De mettre en place un tri pour catégoriser les incidents en fonction de leur gravité -De définir les actions immédiates et bloquer la production si nécéssaire -De définir les causes racines avec les méthodes 5M et 5 pourquoi -Définition et suivi des actions définitives en élaborant un plan d'action correctif détaillé, en assignant des responsabilités aux personnes concernées et en définissant des échéances . Le système assure un suivi de l'avancement des actions et permet une validation une fois les actions terminées. | K39: RAS | L39: Mahdi B. | M39: Validée par le client | N39: 0 | O39: =Tableau3[[#This Row],[HJ Dev]]*(25%+25%) -> 0 | P39: =Tableau3[[#This Row],[HJ Analyse et Test]]+Tableau3[[#This Row],[HJ Dev]] -> 0 | Q39: N/A | R39: N/A | S39: N/A | T39: N/A | U39: N/A
B40: E028 | C40: Historisation des déclarations de non conformités | D40: Fonctionnelle | E40: SF-Fonctionnelle | F40: Commerciale | G40: Fournir un historique détaillé des déclarations de non-conformité | H40: Workshop/réunion client | I40: Standard | J40: La solution offre une interface "Détail Qualité" permettant d'historiser tous les déclaration des non-conformité par Atelier , Ligne , OF , produits , client avec une décortication des défauts de chaque déclaration | K40: RAS | L40: Mahdi B. | M40: Validée par le client | N40: 0 | O40: =Tableau3[[#This Row],[HJ Dev]]*(25%+25%) -> 0 | P40: =Tableau3[[#This Row],[HJ Analyse et Test]]+Tableau3[[#This Row],[HJ Dev]] -> 0
B41: E029 | C41: Gestion des outils de mesures | D41: Fonctionnelle | E41: SF-Fonctionnelle | F41: Commerciale | G41: Gérer les outils de mesures de qualité des produits | H41: Workshop/réunion client | I41: Standard | J41: la solution offre un module de gestion des outils de mesure de qualité permet de suivre et gérer les outils de mesures de la qualité des prodduits en mettant en place des études R&R pour évaluer la fiabilité des outils avec un suivi de statut de échantillonnage . | K41: RAS | L41: Mahdi B. | M41: Validée par le client | N41: 0 | O41: =Tableau3[[#This Row],[HJ Dev]]*(25%+25%) -> 0 | P41: =Tableau3[[#This Row],[HJ Analyse et Test]]+Tableau3[[#This Row],[HJ Dev]] -> 0
B42: E030 | C42: Fiches Qualité | D42: Fonctionnelle | E42: SF-Fonctionnelle | F42: Commerciale | G42: Gérer les gammes de contrôles et générer des fiches de qualité selon des fréquences paramétrables et des événements | H42: Workshop/réunion client | I42: Standard | J42: La solution propose un module de gestion des gammes de contrôle offrant les fonctionnalités suivantes : -Définition de gammes de contrôle: Configuration détaillée des critères de contrôle (visuels, dimensionnels), des paramètres de réglage du processus, des tolérances et des fréquences de génération des fiches. -Génération automatisée de fiches de contrôle: Création automatique de fiches de démarrage, de fin de série et de suivi en fonction des événements de production (lancement, suspension, clôture d'OF) et des fréquences définies , ainsi que des fiches de suivi périodiques en fonction des fréquences définies. Workflow de validation et suivi: Implémentation d'un workflow de validation multi-niveaux (opérateur, contrôleur qualité, etc.) et stockage d'un historique complet des fiches pour une traçabilité optimale. Adaptation : -Ajouter l’option de création des fiches de contrôle par événement (par exemple, un arrêt de type X). -Ajouter la possibilité de joindre un rapport de contrôle laboratoire aux fiches de contrôle (fiche de suivi, fiche de démarrage et fiche de fin de série). -Ajouter un accées rapide au instruction de travail a partir des fiches de contrôle (fiche de suivi, fiche de démarrage et fiche de fin de série). | K42: RAS | L42: Mahdi B. | M42: Validée par le client | N42: 0 | O42: =Tableau3[[#This Row],[HJ Dev]]*(25%+25%) -> 0 | P42: =Tableau3[[#This Row],[HJ Analyse et Test]]+Tableau3[[#This Row],[HJ Dev]] -> 0
B43: E031 | C43: Alarme d'inspection qualité par fréquence par événement | D43: Fonctionnelle | E43: SF-Fonctionnelle | F43: Commerciale | G43: Configuration d'alertes automatiques pour planifier et exécuter les inspections qualité selon des fréquences prédéfinies | H43: Workshop/réunion client | I43: Standard | J43: La solution permet de gérer les notifications et les alertes pour exécuter les inspections qualité. | K43: RAS | L43: Mahdi B. | M43: Validée par le client | N43: 1.5 | O43: =Tableau3[[#This Row],[HJ Dev]]*(25%+25%) -> 0.75 | P43: =Tableau3[[#This Row],[HJ Analyse et Test]]+Tableau3[[#This Row],[HJ Dev]] -> 2.25
B44: E032 | C44: Suivi MSP | D44: Fonctionnelle | E44: SF-Fonctionnelle | F44: Commerciale | G44: Analyse de la capabilité et anticipation des écarts des processus de production avec des cartes de contrôle MSP. | H44: Workshop/réunion client | I44: Standard | J44: La solution offre un module "MSP" permettant de : - -Spécifier les caractéristiques spéciaux à surveiller, les tolérances associées et la fréquence de collecte des données. -Évaluer la stabilité du processus de production en calculant des indices de capabilité (Cp, Cpk) -Mettre en œuvre des contrôles statistiques en temps réel (moyenne, écart-type) et mettre à jour les limites de contrôle -Suivre et anticiper les variations de qualité: des processus avec des cartes de contrôle et identifier les tendances et les déviations significatives. -Configurer des alertes automatiques pour signaler les dépassements des limites de contrôle ou les variations inattendues | K44: RAS | L44: Mahdi B. | M44: Validée par le client | N44: 0 | O44: =Tableau3[[#This Row],[HJ Dev]]*(25%+25%) -> 0 | P44: =Tableau3[[#This Row],[HJ Analyse et Test]]+Tableau3[[#This Row],[HJ Dev]] -> 0
...

Sheet Params
B2: BU | C2: Nature | D2: Exigence identifiée pendant la phase | E2: Source | F2: Oui/Non | G2: Statut Client | H2: Statut Interne | I2: Catégorie
B3: SF | C3: Fonctionnelle | D3: Commerciale | E3: CdC client | F3: Oui | G3: Validée par le client | H3: Validée | I3: *** SF
B4: R&D | C4: Performance | D4: Conception | E4: Workshop/réunion client | F4: Non | G4: Non validée par client | H4: Non validée | I4: SF-Processus
B5: A définir | C5: Reglementaire | D5: Réalisation | E5: Workshop/réunion Interne | F5: N/A | G5: N/A | H5: N/A | I5: SF-Fonctionnelle
B6: A définir | C6: Sécurité | D6: Mise en œuvre | E6: Standards client | I6: SF-Connectivité Machine
C7: Standard Client | D7: Support et maintenance | E7: Standards MOMSOFT | I7: SF-Intégration SI
C8: Standard MOMSOFT | E8: Reglementation | I8: SF-Software
E9: Demande modification | I9: SF-Infra IT
I11: *** TC
I12: TC-Prestations sur site client

Sheet Modifs Doc
B3: Gestion Exigences Projet
B5: ='Gestion Exigences'!B5 -> Client | D5: ='Gestion Exigences'!D5 -> SIAM
B6: ='Gestion Exigences'!B6 -> Projet | D6: ='Gestion Exigences'!D6 -> Digitalisation Usine
B7: ='Gestion Exigences'!B7 -> Réf BPA du Devis | D7: ='Gestion Exigences'!D7 -> S0-00xyz
B8: ='Gestion Exigences'!B8 -> Réf BPA du Projet | D8: ='Gestion Exigences'!D8 -> PR-22-0xyz
B10: ='Gestion Exigences'!B10 -> Réf Modèle Document | C10: ='Gestion Exigences'!D10 -> MD203
B11: ='Gestion Exigences'!B11 -> Version Modèle Document | C11: ='Gestion Exigences'!D11 -> V1.5
B13: Version | C13: Date | D13: Modifications | E13: Auteur(s) | F13: Vérificateur(s) | G13: Approbateur
B14: V1.0 | C14: 45342 | D14: Version initiale | E14: Nihel K. | F14: Mahdi B. + Ferjania BA | G14: Imed A.
B15: V1.1 | C15: 45701 | D15: Adaptation des paramètres et du logo | E15: Moatez D. | F15: Mahdi B. | G15: Imed A.
B16: V1.2 | C16: 45786 | D16: Adaptation du logo | E16: Moatez D. | F16: Mahdi B. | G16: Imed A.
